Workbook
Name ERM_Identifiers: Materials!$B:$B

Sheet Test_conditions
A1: GRACIOUS | B1: Test Data Recording Form (TDRF)
A2: Please complete all applicable fields below as far as possible. Aim to familiarise yourself with the Introductory Guidance and Example Filled Templates.
A3: While aiming to standardise data recording as far as we can, flexibility may still be needed for some Test/Assay types and their results:
A4: Thus it may be necessary to add additional items e.g. for further replicates, concentrations, timepoints, or other variations on inputs, results outputs, etc.
A5: If so, please highlight changes & alterations e.g. using colour, and/or comments in notes, or adjacent to data/tables to flag items, fluctuations from norm, etc.
A6: TEST CONDITIONS | B6: Please ensure you also complete a Test Method Description Form (TMDF) for this test type
A8: Project Work Package | B8: wp3 | F8: Linked exeriment identifier
A9: Partner conducting test/assay | B9: TEST1
A10: Test facility - Laboratory name | B10: TEST2
A11: Lead Scientist & contact for test | B11: ME
A12: Assay/Test work conducted by | B12: ME
A13: Full name of test/assay | B13: Alamar blue
A14: Short name or acronym for test/assay | B14: Alamar blue
A15: Type or class of experimental test as used here | B15: ENM_0000068_SECTION
A16: End-Point being investigated/assessed by the test | B16: Relative cell viability (average exp) | C16: Relative cell viability
A17: End-Point units | B17: % | C17: %
A18: Raw data metrics | B18: Absorbance
A19: Raw data units | B19: AU
A20: SOP(s) for test | B20: ok
A21: Path/link to sop/protocol
A22: Test start date | B22: 2026-02-16
A23: Test end date | B23: 2026-02-16
A24: Test Material Details
A25: Select item from Project Materials list | B25: Ag-NW2_short | C25: DPP_nano
A26: Material Name | B26: =VLOOKUP(B$25,Materials!$B:$J,"3",FALSE) -> Ag, 3 um length, 50 nm diameter | C26: =VLOOKUP(C$25,Materials!$B:$J,"3",FALSE) -> organic pigment Red 254 transparent, diketopyrrolopyrrole, 43nm, hydrophobic
A27: Core chemistry | B27: =VLOOKUP(B$25,Materials!$B:$J,"9",FALSE) -> Ag | C27: =VLOOKUP(C$25,Materials!$B:$J,"9",FALSE) -> 0
A28: CAS No | B28: =VLOOKUP(B$25,Materials!$B:$J,"4",FALSE) -> 7440-22-4 | C28: =VLOOKUP(C$25,Materials!$B:$J,"4",FALSE) -> 84632-65-5
A29: Material Supplier | B29: =VLOOKUP(B$25,Materials!$B:$J,"6",FALSE) -> NanoGap | C29: =VLOOKUP(C$25,Materials!$B:$J,"6",FALSE) -> BASF
A30: Material State
A31: Batch | B31: =VLOOKUP(B$25,Materials!$B:$J,"8",FALSE) -> 0 | C31: =VLOOKUP(C$25,Materials!$B:$J,"8",FALSE) -> 0
A32: Date of preparation | B32: 2026-02-16 | C32: 2026-02-16
A33: DISPERSION
A34: Standard dispersion protocol
A35: Dispersion agent
A36: CELL LINE DETAILS
A37: Cell line short-name | B37: Caco2
A38: Supplier | B38: a
A39: Passage no | B39: b
A40: Plate details | B40: b
A41: Number of readings | B41: 2
...

Sheet Raw_data_TABLE
A1: Material | B1: Time | C1: Concentration | D1: Replicate | E1: Absorbance
B2: h | C2: ug/cm2 | E2: AU
A3: Ag-NW2_short | B3: 1 | C3: 0 | D3: 1 | E3: =RAND() -> 0.48075978
A4: Ag-NW2_short | B4: 1 | C4: 10 | D4: 1 | E4: =E3*1.2 + RAND() -> 1.0665317
A5: Ag-NW2_short | B5: 1 | C5: 100 | D5: 1 | E5: =E4*1.2 + RAND() -> 2.268881
A6: Ag-NW2_short | B6: 1 | C6: 0 | D6: 2 | E6: =RAND() -> 0.25649261
A7: Ag-NW2_short | B7: 1 | C7: 10 | D7: 2 | E7: =E6*1.2 + RAND() -> 0.97705386
A8: Ag-NW2_short | B8: 1 | C8: 100 | D8: 2 | E8: =E7*1.2 + RAND() -> 2.0848932
A9: DPP_nano | B9: 1 | C9: 0 | D9: 1 | E9: =RAND() -> 0.16209279
A10: DPP_nano | B10: 1 | C10: 10 | D10: 1 | E10: =E9*1.2 + RAND() -> 0.30701433
A11: DPP_nano | B11: 1 | C11: 100 | D11: 1 | E11: =E10*1.2 + RAND() -> 0.80737855
A12: DPP_nano | B12: 1 | C12: 0 | D12: 2 | E12: =RAND() -> 0.4234073
A13: DPP_nano | B13: 1 | C13: 10 | D13: 2 | E13: =E12*1.2 + RAND() -> 1.5036942
A14: DPP_nano | B14: 1 | C14: 100 | D14: 2 | E14: =E13*1.2 + RAND() -> 2.5198441

Sheet Results_TABLE
A1: Material | B1: Time | C1: Concentration | D1: Relative cell viability (average exp) | E1: Relative cell viability
D2: % | E2: %
A3: Ag-NW2_short | C3: 0 | D3: 0.001416166 | E3: 0.001416166
A4: Ag-NW2_short | C4: 10 | D4: 0.92241504 | E4: 0.92241504
A5: Ag-NW2_short | C5: 100 | D5: 1.116305 | E5: 1.116305
A6: DPP_nano | C6: 0 | D6: 0.001416166 | E6: 0.001416166
A7: DPP_nano | C7: 10 | D7: 0.92241504 | E7: 0.92241504
A8: DPP_nano | C8: 100 | D8: 1.116305 | E8: 1.116305

Sheet Materials
B1: ERM identifier | C1: ID | D1: Name | E1: CAS | F1: type | G1: Supplier | H1: Supplier code | I1: Batch | J1: Core | K1: BET surface in m²/g
B2: Ag-NW2_short | C2: Ag-NW2_short | D2: Ag, 3 um length, 50 nm diameter | E2: 7440-22-4 | F2: NPO_1892 | G2: NanoGap | J2: Ag
B3: Ag-NW1_long | C3: Ag-NW1_long | D3: Ag, 30 µm length, 100 nm diameter | E3: 7440-22-4 | F3: NPO_1892 | G3: NanoGap | J3: Ag
B4: CuPhthalo_halogen | C4: CuPhthalo_halogen | D4: Organic pigment Green 7, CuPhthalocyanine 14nm hydrophobic | E4: 1328-53-6 | F4: CHEBI_59999 | G4: BASF
B5: CuPhthalo_nano | C5: CuPhthalo_nano | D5: Organic pigment Blue 15, Cu-Phthalocyanine 17nm, hydrophobic | E5: 147-14-8 | F5: CHEBI_59999 | G5: BASF
B6: DPP_premixed | C6: DPP_premixed | D6: Organic pigment Red 254 opaque, diketopyrrolopyrrole, 230nm, borderline hydrophobic | E6: 84632-65-5 | F6: CHEBI_59999 | G6: BASF
B7: DPP_nano | C7: DPP_nano | D7: organic pigment Red 254 transparent, diketopyrrolopyrrole, 43nm, hydrophobic | E7: 84632-65-5 | F7: CHEBI_59999 | G7: BASF
B8: DPP_non-nano | C8: DPP_non-nano | D8: organic pigment Red 254 opaque, diketopyrrolopyrrole, 233nm, hydrophobic | E8: 84632-65-5 | F8: CHEBI_59999 | G8: BASF
B9: Fe2O3_nano_A | C9: Fe2O3_nano_A | D9: Inorganic pigment Red 101, rods, hydrophilic | E9: 1309-37-1 | F9: NPO_1550 | G9: BASF | J9: Fe2O3
B10: Fe2O3_nano_B | C10: Fe2O3_nano_B | D10: Inorganic pigment Red 101, 37nm, hydrophilic | E10: 1309-37-1 | F10: NPO_1550 | G10: BASF | J10: Fe2O3
B11: FeOOH | C11: FeOOH | D11: Iron(III) oxide-hydroxide | E11: 1310-14-1 | F11: NPO_1550 | G11: ?? | J11: O=[Fe]O
B12: Fe2O3_larger | C12: Fe2O3_larger | D12: diiron trioxide | E12: 1309-37-1 | F12: NPO_1550 | G12: ?? | J12: [O-2].[O-2].[O-2].[Fe+3].[Fe+3].O
B13: Silica_Al | C13: Silica_Al | D13: Silicon dioxide, Al substituted into the silica surface, 25% | E13: 7631-86-9 | F13: NPO_1373 | G13: NOURYON | J13: SiO2
B14: Silica_std | C14: Silica_std | D14: Silicon dioxide, Standard silica, 30% | E14: 7631-86-9 | F14: NPO_1373 | G14: NOURYON | J14: SiO2
B15: CeO2 (pyrolytic) | C15: CeO2 (pyrolytic) | D15: Pyrolytic, 34.75 nm ± 22.89 | E15: 1306-38-3 | F15: ENM_9000006 | J15: CeO2
B16: Silica_Silane | C16: Silica_Silane | D16: Silicon dioxide, silane modified, 28% | E16: 7631-86-9 | F16: NPO_1373 | G16: NOURYON | J16: SiO2
B17: Silica_anis_Std | C17: Silica_anis_Std | D17: Silicon dioxide, Standard silica, aggregated nanoparticles, 12% SiO2, pH 11 | E17: 7631-86-9 | F17: NPO_1373 | G17: NOURYON | J17: SiO2
B18: Silica_anis_Al | C18: Silica_anis_Al | D18: Silicon dioxide, Al substituted into the surface, aggregated nanoparticles, 7% total solids, pH 8.5 | E18: 7631-86-9 | F18: NPO_1373 | G18: NOURYON
B19: ZnCdSeS | C19: ZnCdSeS | D19: ZnCdSeS, hydrophobic (530nm) | F19: NPO_589 | G19: PlasmaChem | J19: ZnCdSeS
B20: ZnCdSeS-COOH | C20: ZnCdSeS-COOH | D20: ZnCdSeS-COOH, hydrophilic (530nm) | F20: NPO_589 | G20: PlasmaChem | J20: ZnCdSeS
B21: ZnCuInS/ZnS | C21: ZnCuInS/ZnS | D21: ZnCuInS/ZnS, hydrophobic (530nm) | F21: NPO_589 | G21: PlasmaChem | J21: Zn Cu In S
B22: ZnCuInS/ZnS-COOH_smaller | C22: ZnCuInS/ZnS-COOH_smaller, hydrophilic (530nm) | D22: ZnCuInS/ZnS-COOH_smaller | F22: NPO_589 | G22: PlasmaChem | J22: Zn Cu In S
B23: ZnCuInS/ZnS-COOH_larger | C23: ZnCuInS/ZnS-COOH_larger | D23: ZnCuInS/ZnS-COOH_larger, hydrophilic (700nm) | F23: NPO_589 | G23: PlasmaChem | J23: Zn Cu In S
B24: CNF-50-nm | C24: CNF-50-nm | D24: Cellulose nanofibrils 50 nm diameter x 6.6 µm length | E24: 9004-34-6 | F24: CHEBI:133349 | G24: Harvard | J24: Cellulose
B25: CNF-80-nm | C25: CNF-80-nm | D25: Cellulose nanofibrils 80 nm diameter x 6.6 µm length | E25: 9004-34-6 | F25: CHEBI:133349 | G25: Harvard | J25: Cellulose
B26: Cellulose nanocrystals | C26: Cellulose nanocrystals | D26: Cellulose nanocrystals 25 nm x 250 nm rod-like | E26: 9004-34-6 | F26: NPO_1375 | G26: Harvard | J26: Cellulose
B27: CNT Mitsui 7 | C27: CNT Mitsui 7 | D27: Mitsui 7 | E27: 308068-56-6 | F27: NPO_354 | G27: JRC | J27: Carbon
B28: NM-300 | C28: NM-300 | D28: NM-300 | E28: 7440-22-4 | F28: NPO_1892 | G28: JRC | J28: Ag
B29: NM-220 | C29: NM-220 | D29: NM-220 | E29: 7727-43-7 | F29: CHEBI_133326 | G29: JRC | J29: BaSO4
B30: NM-200 | C30: NM-200 | D30: NM-200 | E30: 7631-86-9 | G30: JRC | J30: SiO2
B31: NM-110 | C31: NM-110 | D31: NM-110 | E31: 1314-13-2 | G31: JRC | J31: ZnO
B32: NM-402 | C32: NM-402 | D32: MWCNT | F32: NPO_354 | G32: JRC | J32: Carbon
B33: NM-212 | C33: NM-212 | D33: Cerium dioxide | E33: 1306-38-3 | F33: ENM_9000006 | G33: JRC | J33: CeO2
B34: CuO | C34: CuO | D34: Copper(II) oxide | E34: 1317-38-0 | F34: NPO_1544 | J34: [Cu]=O
B35: Mn2O3 | C35: Mn2O3 | D35: Manganese(III) oxide | E35: 1317-34-6 | F35: ENM_9000073 | J35: O=[Mn]O[Mn]=O

Sheet plate_metadata
A1: readout | B1: 1 | C1: 2 | D1: 3 | E1: 4 | F1: 5 | G1: 6 | H1: 7 | I1: 8 | J1: 9 | K1: 10 | L1: 11 | M1: 12
A2: A | B2: =B$1+RAND() -> 1.0654856 | C2: =C$1+RAND() -> 2.0259036 | D2: =D$1+RAND() -> 3.8898984 | E2: =E$1+RAND() -> 4.8897775 | F2: =F$1+RAND() -> 5.3704815 | G2: =G$1+RAND() -> 6.1453969 | H2: =H$1+RAND() -> 7.2185795 | I2: =I$1+RAND() -> 8.3929061 | ... M2: =M$1+RAND() -> 12.300532
A3: B | B3: =B$1+RAND() -> 1.5495357 | C3: =C$1+RAND() -> 2.1205711 | D3: =D$1+RAND() -> 3.6412026 | E3: =E$1+RAND() -> 4.4622763 | F3: =F$1+RAND() -> 5.3861818 | G3: =G$1+RAND() -> 6.2263505 | H3: =H$1+RAND() -> 7.1138627 | I3: =I$1+RAND() -> 8.2268862 | ... M3: =M$1+RAND() -> 12.140487
A4: C | B4: =B$1+RAND() -> 1.6564152 | C4: =C$1+RAND() -> 2.6743901 | D4: =D$1+RAND() -> 3.907441 | E4: =E$1+RAND() -> 4.2722282 | F4: =F$1+RAND() -> 5.47232 | G4: =G$1+RAND() -> 6.1871061 | H4: =H$1+RAND() -> 7.1641865 | I4: =I$1+RAND() -> 8.9636158 | ... M4: =M$1+RAND() -> 12.22219
A5: D | B5: =B$1+RAND() -> 1.3008375 | C5: =C$1+RAND() -> 2.6481141 | D5: =D$1+RAND() -> 3.0331857 | E5: =E$1+RAND() -> 4.1240251 | F5: =F$1+RAND() -> 5.2202016 | G5: =G$1+RAND() -> 6.12785 | H5: =H$1+RAND() -> 7.9316991 | I5: =I$1+RAND() -> 8.2813754 | ... M5: =M$1+RAND() -> 12.554285
A6: E | B6: =B$1+RAND() -> 1.9765631 | C6: =C$1+RAND() -> 2.4505762 | D6: =D$1+RAND() -> 3.1020444 | E6: =E$1+RAND() -> 4.7514084 | F6: =F$1+RAND() -> 5.0496998 | G6: =G$1+RAND() -> 6.6066605 | H6: =H$1+RAND() -> 7.2735232 | I6: =I$1+RAND() -> 8.1037387 | ... M6: =M$1+RAND() -> 12.28815
A7: F | B7: =B$1+RAND() -> 1.3730592 | C7: =C$1+RAND() -> 2.1547523 | D7: =D$1+RAND() -> 3.2659351 | E7: =E$1+RAND() -> 4.8979525 | F7: =F$1+RAND() -> 5.1384703 | G7: =G$1+RAND() -> 6.4102805 | H7: =H$1+RAND() -> 7.5495401 | I7: =I$1+RAND() -> 8.1469858 | ... M7: =M$1+RAND() -> 12.336203
A8: G | B8: =B$1+RAND() -> 1.466396 | C8: =C$1+RAND() -> 2.9628419 | D8: =D$1+RAND() -> 3.088866 | E8: =E$1+RAND() -> 4.937047 | F8: =F$1+RAND() -> 5.2603538 | G8: =G$1+RAND() -> 6.6471821 | H8: =H$1+RAND() -> 7.3892677 | I8: =I$1+RAND() -> 8.4166025 | ... M8: =M$1+RAND() -> 12.174448
A9: H | B9: =B$1+RAND() -> 1.0514389 | C9: =C$1+RAND() -> 2.3264684 | D9: =D$1+RAND() -> 3.8653795 | E9: =E$1+RAND() -> 4.6425387 | F9: =F$1+RAND() -> 5.3872434 | G9: =G$1+RAND() -> 6.8073616 | H9: =H$1+RAND() -> 7.3858507 | I9: =I$1+RAND() -> 8.4945984 | ... M9: =M$1+RAND() -> 12.56001

Sheet plate_readout
A1: readout | B1: 1 | C1: 2 | D1: 3 | E1: 4 | F1: 5 | G1: 6 | H1: 7 | I1: 8 | J1: 9 | K1: 10 | L1: 11 | M1: 12
A2: A | B2: a1 | C2: a2 | D2: a3 | E2: a4 | F2: a5 | G2: a6 | H2: a7 | I2: a8 | J2: a9 | K2: a10 | L2: a11 | M2: a12
A3: B | B3: =B$1+RAND() -> 1.6678101 | C3: =C$1+RAND() -> 2.2872568 | D3: =D$1+RAND() -> 3.2491019 | E3: =E$1+RAND() -> 4.1890876 | F3: =F$1+RAND() -> 5.3512551 | G3: =G$1+RAND() -> 6.2147719 | H3: =H$1+RAND() -> 7.3298358 | I3: =I$1+RAND() -> 8.9357967 | ... M3: =M$1+RAND() -> 12.5709
A4: C | B4: =B$1+RAND() -> 1.8305619 | C4: =C$1+RAND() -> 2.6967785 | D4: =D$1+RAND() -> 3.7677593 | E4: =E$1+RAND() -> 4.6420597 | F4: =F$1+RAND() -> 5.0031305 | G4: =G$1+RAND() -> 6.7074611 | H4: =H$1+RAND() -> 7.48353 | I4: =I$1+RAND() -> 8.5941732 | ... M4: =M$1+RAND() -> 12.791101
A5: D | B5: d1 | C5: d2 | D5: d3 | E5: d4 | F5: d5 | G5: d6 | H5: d7 | I5: d8 | J5: d9 | K5: d10 | L5: d11 | M5: d12
A6: E | B6: =B$1+RAND() -> 1.043854 | C6: =C$1+RAND() -> 2.6952945 | D6: =D$1+RAND() -> 3.526497 | E6: =E$1+RAND() -> 4.4123058 | F6: =F$1+RAND() -> 5.6723719 | G6: =G$1+RAND() -> 6.8786952 | H6: =H$1+RAND() -> 7.2484456 | I6: =I$1+RAND() -> 8.4844905 | ... M6: =M$1+RAND() -> 12.995786
A7: F | B7: =B$1+RAND() -> 1.4167415 | C7: =C$1+RAND() -> 2.5811061 | D7: =D$1+RAND() -> 3.0283257 | E7: =E$1+RAND() -> 4.564723 | F7: =F$1+RAND() -> 5.3105142 | G7: =G$1+RAND() -> 6.1335888 | H7: =H$1+RAND() -> 7.601665 | I7: =I$1+RAND() -> 8.1893204 | ... M7: =M$1+RAND() -> 12.985324
A8: G | B8: =B$1+RAND() -> 1.0985104 | C8: =C$1+RAND() -> 2.0904356 | D8: =D$1+RAND() -> 3.0682423 | E8: =E$1+RAND() -> 4.5518913 | F8: =F$1+RAND() -> 5.7556153 | G8: =G$1+RAND() -> 6.4126592 | H8: =H$1+RAND() -> 7.0994491 | I8: =I$1+RAND() -> 8.7630973 | ... M8: =M$1+RAND() -> 12.443779
A9: H | B9: =B$1+RAND() -> 1.6162905 | C9: =C$1+RAND() -> 2.3785493 | D9: =D$1+RAND() -> 3.8622835 | E9: =E$1+RAND() -> 4.0892434 | F9: =F$1+RAND() -> 5.5980639 | G9: =G$1+RAND() -> 6.4164722 | H9: =H$1+RAND() -> 7.2685464 | I9: =I$1+RAND() -> 8.4313673 | ... L9: =L$1+RAND() -> 11.826742 | M9: h12

Sheet plate_materials
A1: readout | B1: 1 | C1: 2 | D1: 3 | E1: 4 | F1: 5 | G1: 6 | H1: 7 | I1: 8 | J1: 9 | K1: 10 | L1: 11 | M1: 12
A2: A | B2: M1 | C2: M2 | D2: M3 | E2: M4 | F2: M5 | G2: M6 | H2: M7 | I2: M8 | J2: M9 | K2: M10 | L2: M11 | M2: M12
A3: B | B3: M1 | C3: M2 | D3: M3 | E3: M4 | F3: M5 | G3: M6 | H3: M7 | I3: M8 | J3: M9 | K3: M10 | L3: M11 | M3: M12
A4: C | B4: M1 | C4: M2 | D4: M3 | E4: M4 | F4: M5 | G4: M6 | H4: M7 | I4: M8 | J4: M9 | K4: M10 | L4: M11 | M4: M12
A5: D | B5: M1 | C5: M2 | D5: M3 | E5: M4 | F5: M5 | G5: M6 | H5: M7 | I5: M8 | J5: M9 | K5: M10 | L5: M11 | M5: M12
A6: E | B6: M1 | C6: M2 | D6: M3 | E6: M4 | F6: M5 | G6: M6 | H6: M7 | I6: M8 | J6: M9 | K6: M10 | L6: M11 | M6: M12
A7: F | B7: M1 | C7: M2 | D7: M3 | E7: M4 | F7: M5 | G7: M6 | H7: M7 | I7: M8 | J7: M9 | K7: M10 | L7: M11 | M7: M12
A8: G | B8: M1 | C8: M2 | D8: M3 | E8: M4 | F8: M5 | G8: M6 | H8: M7 | I8: M8 | J8: M9 | K8: M10 | L8: M11 | M8: M12
A9: H | B9: M1 | C9: M2 | D9: M3 | E9: M4 | F9: M5 | G9: M6 | H9: M7 | I9: M8 | J9: M9 | K9: M10 | L9: M11 | M9: M12

Sheet plate_table
A1: README | D1: row | E1: col | F1: value | G1: materials | H1: concentration
D2: =INDEX(plate_readout!$A$2:$A$9, INT((ROW()-2)/(COLUMNS(plate_readout!$B$2:$M$9)))+1) -> A | E2: =INDEX(plate_readout!$B$1:$M$1,MOD(ROW()-2,COLUMNS(plate_readout!$B$2:$M$9))+1) -> 1 | F2: =INDEX(plate_readout!$B$2:$M$9, INT((ROW()-2)/COLUMNS(plate_readout!$B$2:$M$9))+1, MOD(ROW()-2, COLUMNS(plate_readout!$B$2:$M$9))+1) -> a1 | G2: =INDEX(plate_materials!$B$2:$M$9, INT((ROW()-2)/COLUMNS(plate_materials!$B$2:$M$9))+1, MOD(ROW()-2, COLUMNS(plate_materials!$B$2:$M$9))+1) -> M1 | H2: =INDEX(plate_metadata!$B$2:$M$9, INT((ROW()-2)/COLUMNS(plate_metadata!$B$2:$M$9))+1, MOD(ROW()-2, COLUMNS(plate_metadata!$B$2:$M$9))+1) -> 1.0654856
D3: =INDEX(plate_readout!$A$2:$A$9, INT((ROW()-2)/(COLUMNS(plate_readout!$B$2:$M$9)))+1) -> A | E3: =INDEX(plate_readout!$B$1:$M$1,MOD(ROW()-2,COLUMNS(plate_readout!$B$2:$M$9))+1) -> 2 | F3: =INDEX(plate_readout!$B$2:$M$9, INT((ROW()-2)/COLUMNS(plate_readout!$B$2:$M$9))+1, MOD(ROW()-2, COLUMNS(plate_readout!$B$2:$M$9))+1) -> a2 | G3: =INDEX(plate_materials!$B$2:$M$9, INT((ROW()-2)/COLUMNS(plate_materials!$B$2:$M$9))+1, MOD(ROW()-2, COLUMNS(plate_materials!$B$2:$M$9))+1) -> M2 | H3: =INDEX(plate_metadata!$B$2:$M$9, INT((ROW()-2)/COLUMNS(plate_metadata!$B$2:$M$9))+1, MOD(ROW()-2, COLUMNS(plate_metadata!$B$2:$M$9))+1) -> 2.0259036
D4: =INDEX(plate_readout!$A$2:$A$9, INT((ROW()-2)/(COLUMNS(plate_readout!$B$2:$M$9)))+1) -> A | E4: =INDEX(plate_readout!$B$1:$M$1,MOD(ROW()-2,COLUMNS(plate_readout!$B$2:$M$9))+1) -> 3 | F4: =INDEX(plate_readout!$B$2:$M$9, INT((ROW()-2)/COLUMNS(plate_readout!$B$2:$M$9))+1, MOD(ROW()-2, COLUMNS(plate_readout!$B$2:$M$9))+1) -> a3 | G4: =INDEX(plate_materials!$B$2:$M$9, INT((ROW()-2)/COLUMNS(plate_materials!$B$2:$M$9))+1, MOD(ROW()-2, COLUMNS(plate_materials!$B$2:$M$9))+1) -> M3 | H4: =INDEX(plate_metadata!$B$2:$M$9, INT((ROW()-2)/COLUMNS(plate_metadata!$B$2:$M$9))+1, MOD(ROW()-2, COLUMNS(plate_metadata!$B$2:$M$9))+1) -> 3.8898984
D5: =INDEX(plate_readout!$A$2:$A$9, INT((ROW()-2)/(COLUMNS(plate_readout!$B$2:$M$9)))+1) -> A | E5: =INDEX(plate_readout!$B$1:$M$1,MOD(ROW()-2,COLUMNS(plate_readout!$B$2:$M$9))+1) -> 4 | F5: =INDEX(plate_readout!$B$2:$M$9, INT((ROW()-2)/COLUMNS(plate_readout!$B$2:$M$9))+1, MOD(ROW()-2, COLUMNS(plate_readout!$B$2:$M$9))+1) -> a4 | G5: =INDEX(plate_materials!$B$2:$M$9, INT((ROW()-2)/COLUMNS(plate_materials!$B$2:$M$9))+1, MOD(ROW()-2, COLUMNS(plate_materials!$B$2:$M$9))+1) -> M4 | H5: =INDEX(plate_metadata!$B$2:$M$9, INT((ROW()-2)/COLUMNS(plate_metadata!$B$2:$M$9))+1, MOD(ROW()-2, COLUMNS(plate_metadata!$B$2:$M$9))+1) -> 4.8897775
D6: =INDEX(plate_readout!$A$2:$A$9, INT((ROW()-2)/(COLUMNS(plate_readout!$B$2:$M$9)))+1) -> A | E6: =INDEX(plate_readout!$B$1:$M$1,MOD(ROW()-2,COLUMNS(plate_readout!$B$2:$M$9))+1) -> 5 | F6: =INDEX(plate_readout!$B$2:$M$9, INT((ROW()-2)/COLUMNS(plate_readout!$B$2:$M$9))+1, MOD(ROW()-2, COLUMNS(plate_readout!$B$2:$M$9))+1) -> a5 | G6: =INDEX(plate_materials!$B$2:$M$9, INT((ROW()-2)/COLUMNS(plate_materials!$B$2:$M$9))+1, MOD(ROW()-2, COLUMNS(plate_materials!$B$2:$M$9))+1) -> M5 | H6: =INDEX(plate_metadata!$B$2:$M$9, INT((ROW()-2)/COLUMNS(plate_metadata!$B$2:$M$9))+1, MOD(ROW()-2, COLUMNS(plate_metadata!$B$2:$M$9))+1) -> 5.3704815
D7: =INDEX(plate_readout!$A$2:$A$9, INT((ROW()-2)/(COLUMNS(plate_readout!$B$2:$M$9)))+1) -> A | E7: =INDEX(plate_readout!$B$1:$M$1,MOD(ROW()-2,COLUMNS(plate_readout!$B$2:$M$9))+1) -> 6 | F7: =INDEX(plate_readout!$B$2:$M$9, INT((ROW()-2)/COLUMNS(plate_readout!$B$2:$M$9))+1, MOD(ROW()-2, COLUMNS(plate_readout!$B$2:$M$9))+1) -> a6 | G7: =INDEX(plate_materials!$B$2:$M$9, INT((ROW()-2)/COLUMNS(plate_materials!$B$2:$M$9))+1, MOD(ROW()-2, COLUMNS(plate_materials!$B$2:$M$9))+1) -> M6 | H7: =INDEX(plate_metadata!$B$2:$M$9, INT((ROW()-2)/COLUMNS(plate_metadata!$B$2:$M$9))+1, MOD(ROW()-2, COLUMNS(plate_metadata!$B$2:$M$9))+1) -> 6.1453969
D8: =INDEX(plate_readout!$A$2:$A$9, INT((ROW()-2)/(COLUMNS(plate_readout!$B$2:$M$9)))+1) -> A | E8: =INDEX(plate_readout!$B$1:$M$1,MOD(ROW()-2,COLUMNS(plate_readout!$B$2:$M$9))+1) -> 7 | F8: =INDEX(plate_readout!$B$2:$M$9, INT((ROW()-2)/COLUMNS(plate_readout!$B$2:$M$9))+1, MOD(ROW()-2, COLUMNS(plate_readout!$B$2:$M$9))+1) -> a7 | G8: =INDEX(plate_materials!$B$2:$M$9, INT((ROW()-2)/COLUMNS(plate_materials!$B$2:$M$9))+1, MOD(ROW()-2, COLUMNS(plate_materials!$B$2:$M$9))+1) -> M7 | H8: =INDEX(plate_metadata!$B$2:$M$9, INT((ROW()-2)/COLUMNS(plate_metadata!$B$2:$M$9))+1, MOD(ROW()-2, COLUMNS(plate_metadata!$B$2:$M$9))+1) -> 7.2185795
D9: =INDEX(plate_readout!$A$2:$A$9, INT((ROW()-2)/(COLUMNS(plate_readout!$B$2:$M$9)))+1) -> A | E9: =INDEX(plate_readout!$B$1:$M$1,MOD(ROW()-2,COLUMNS(plate_readout!$B$2:$M$9))+1) -> 8 | F9: =INDEX(plate_readout!$B$2:$M$9, INT((ROW()-2)/COLUMNS(plate_readout!$B$2:$M$9))+1, MOD(ROW()-2, COLUMNS(plate_readout!$B$2:$M$9))+1) -> a8 | G9: =INDEX(plate_materials!$B$2:$M$9, INT((ROW()-2)/COLUMNS(plate_materials!$B$2:$M$9))+1, MOD(ROW()-2, COLUMNS(plate_materials!$B$2:$M$9))+1) -> M8 | H9: =INDEX(plate_metadata!$B$2:$M$9, INT((ROW()-2)/COLUMNS(plate_metadata!$B$2:$M$9))+1, MOD(ROW()-2, COLUMNS(plate_metadata!$B$2:$M$9))+1) -> 8.3929061
D10: =INDEX(plate_readout!$A$2:$A$9, INT((ROW()-2)/(COLUMNS(plate_readout!$B$2:$M$9)))+1) -> A | E10: =INDEX(plate_readout!$B$1:$M$1,MOD(ROW()-2,COLUMNS(plate_readout!$B$2:$M$9))+1) -> 9 | F10: =INDEX(plate_readout!$B$2:$M$9, INT((ROW()-2)/COLUMNS(plate_readout!$B$2:$M$9))+1, MOD(ROW()-2, COLUMNS(plate_readout!$B$2:$M$9))+1) -> a9 | G10: =INDEX(plate_materials!$B$2:$M$9, INT((ROW()-2)/COLUMNS(plate_materials!$B$2:$M$9))+1, MOD(ROW()-2, COLUMNS(plate_materials!$B$2:$M$9))+1) -> M9 | H10: =INDEX(plate_metadata!$B$2:$M$9, INT((ROW()-2)/COLUMNS(plate_metadata!$B$2:$M$9))+1, MOD(ROW()-2, COLUMNS(plate_metadata!$B$2:$M$9))+1) -> 9.907886
D11: =INDEX(plate_readout!$A$2:$A$9, INT((ROW()-2)/(COLUMNS(plate_readout!$B$2:$M$9)))+1) -> A | E11: =INDEX(plate_readout!$B$1:$M$1,MOD(ROW()-2,COLUMNS(plate_readout!$B$2:$M$9))+1) -> 10 | F11: =INDEX(plate_readout!$B$2:$M$9, INT((ROW()-2)/COLUMNS(plate_readout!$B$2:$M$9))+1, MOD(ROW()-2, COLUMNS(plate_readout!$B$2:$M$9))+1) -> a10 | G11: =INDEX(plate_materials!$B$2:$M$9, INT((ROW()-2)/COLUMNS(plate_materials!$B$2:$M$9))+1, MOD(ROW()-2, COLUMNS(plate_materials!$B$2:$M$9))+1) -> M10 | H11: =INDEX(plate_metadata!$B$2:$M$9, INT((ROW()-2)/COLUMNS(plate_metadata!$B$2:$M$9))+1, MOD(ROW()-2, COLUMNS(plate_metadata!$B$2:$M$9))+1) -> 10.059152
D12: =INDEX(plate_readout!$A$2:$A$9, INT((ROW()-2)/(COLUMNS(plate_readout!$B$2:$M$9)))+1) -> A | E12: =INDEX(plate_readout!$B$1:$M$1,MOD(ROW()-2,COLUMNS(plate_readout!$B$2:$M$9))+1) -> 11 | F12: =INDEX(plate_readout!$B$2:$M$9, INT((ROW()-2)/COLUMNS(plate_readout!$B$2:$M$9))+1, MOD(ROW()-2, COLUMNS(plate_readout!$B$2:$M$9))+1) -> a11 | G12: =INDEX(plate_materials!$B$2:$M$9, INT((ROW()-2)/COLUMNS(plate_materials!$B$2:$M$9))+1, MOD(ROW()-2, COLUMNS(plate_materials!$B$2:$M$9))+1) -> M11 | H12: =INDEX(plate_metadata!$B$2:$M$9, INT((ROW()-2)/COLUMNS(plate_metadata!$B$2:$M$9))+1, MOD(ROW()-2, COLUMNS(plate_metadata!$B$2:$M$9))+1) -> 11.129128
D13: =INDEX(plate_readout!$A$2:$A$9, INT((ROW()-2)/(COLUMNS(plate_readout!$B$2:$M$9)))+1) -> A | E13: =INDEX(plate_readout!$B$1:$M$1,MOD(ROW()-2,COLUMNS(plate_readout!$B$2:$M$9))+1) -> 12 | F13: =INDEX(plate_readout!$B$2:$M$9, INT((ROW()-2)/COLUMNS(plate_readout!$B$2:$M$9))+1, MOD(ROW()-2, COLUMNS(plate_readout!$B$2:$M$9))+1) -> a12 | G13: =INDEX(plate_materials!$B$2:$M$9, INT((ROW()-2)/COLUMNS(plate_materials!$B$2:$M$9))+1, MOD(ROW()-2, COLUMNS(plate_materials!$B$2:$M$9))+1) -> M12 | H13: =INDEX(plate_metadata!$B$2:$M$9, INT((ROW()-2)/COLUMNS(plate_metadata!$B$2:$M$9))+1, MOD(ROW()-2, COLUMNS(plate_metadata!$B$2:$M$9))+1) -> 12.300532
... D97: =INDEX(plate_readout!$A$2:$A$9, INT((ROW()-2)/(COLUMNS(plate_readout!$B$2:$M$9)))+1) -> H | E97: =INDEX(plate_readout!$B$1:$M$1,MOD(ROW()-2,COLUMNS(plate_readout!$B$2:$M$9))+1) -> 12 | F97: =INDEX(plate_readout!$B$2:$M$9, INT((ROW()-2)/COLUMNS(plate_readout!$B$2:$M$9))+1, MOD(ROW()-2, COLUMNS(plate_readout!$B$2:$M$9))+1) -> h12 | G97: =INDEX(plate_materials!$B$2:$M$9, INT((ROW()-2)/COLUMNS(plate_materials!$B$2:$M$9))+1, MOD(ROW()-2, COLUMNS(plate_materials!$B$2:$M$9))+1) -> M12 | H97: =INDEX(plate_metadata!$B$2:$M$9, INT((ROW()-2)/COLUMNS(plate_metadata!$B$2:$M$9))+1, MOD(ROW()-2, COLUMNS(plate_metadata!$B$2:$M$9))+1) -> 12.56001

Sheet TemplateDesigner
A1: uuid | B1: surveyjs
A2: 13ba6ee8-8596-4462-9987-1eda31905d27 | B2: {"SOP": "protocol_sop", "conditions": [{"conditon_name": "Concentration", "condition_unit": "ug/cm2", "condition_type": "c_concentration"}, {"conditon_name": "Time", "condition_unit": "h", "condition_type": "c_time"}, {"conditon_name": "Replicate", "condition_type": "c_replicate_tech"}, {"conditon_name": "Experiment number bio replicate", "condition_type": "c_replicate_bio"}], "PROTOCOL_TOP_CATEGORY": "TOX", "data_sheets": ["data_raw", "data_processed", "data_platelayout"], "METADATA_SAMPLE_INFO": [{"param_sample_name": "Material ID", "param_sample_group": "ID"}, {"param_sample_name": "Material name", "param_sample_group": "NAME"}, {"param_sample_name": "Material supplier", "param_sample_group": "SUPPLIER"}], "template_layout": "dose_response", "template_name": " Alamar blue", "template_author": "workshop Gergana Tancheva", "template_acknowledgment": "anna project", "user_role": ["role_lab", "role_datamgr"], "controls": ["c_control_negative", "c_control_positive"], "PROTOCOL_CATEGORY_CODE": "ENM_0000068_SECTION", "raw_data_report": [{"raw_endpoint": "Absorbance", "raw_aggregate": "RAW_DATA", "raw_unit": "AU", "raw_type": "value_num", "raw_conditions": ["Concentration", "Time", "Replicate"]}], "question3": [{"result_name": "Relative cell viability (average exp)", "result_aggregate": "MEAN", "result_unit": "%", "result_type": "value_num", "results_conditions": ["Concentration", "Time"]}, {"results_conditions": ["Concentration", "Time"], "result_name": "Relative cell viability", "result_aggregate": "MEAN", "result_unit": "%", "result_endpoint_uncertainty": "SD", "result_type": "value_num"}], "RESULTS": "The relative viability of cells in different conditions can be determined by comparing the fluorescence or absorbance readings. Higher readings indicate greater metabolic activity and therefore higher cell viability and proliferation rates.", "METADATA_PARAMETERS": [{"param_name": "Cell line short-name", "param_group": "CELL LINE DETAILS", "param_type": "value_text"}, {"param_name": "Supplier", "param_group": "CELL LINE DETAILS", "param_type": "value_text"}, {"param_name": "Passage no", "param_group": "CELL LINE DETAILS", "param_type": "value_num"}, {"param_name": "Plate details", "param_group": "CELL LINE DETAILS", "param_type": "value_text"}, {"param_name": "Number of readings ", "param_group": "CELL LINE DETAILS", "param_type": "value_text"}, {"param_name": "Number of cells per well", "param_group": "CELL LINE DETAILS", "param_type": "value_text"}, {"param_name": "Total volume per well", "param_group": "CELL LINE DETAILS", "param_type": "value_text"}], "METADATA_SAMPLE_PREP": [{"param_sampleprep_name": "Standard dispersion protocol ", "param_sampleprep_group": "DISPERSION", "param_type": "value_text"}, {"param_sampleprep_name": "Dispersion agent", "param_sampleprep_group": "DISPERSION", "param_type": "value_text"}], "provenance_project": "MOMENTUM", "provenance_workpackage": "wp3", "origin_uuid": "18804da3-fa42-4d09-8278-685b5c7b3f3a", "METHOD": "Alamar blue", "EXPERIMENT": "ok", "template_uuid": "13ba6ee8-8596-4462-9987-1eda31905d27"}
A3: version | B3: 1.01
